<?xml version="1.0"?>
<sdf version='1.5'>
  <model name='delta_wing'>
    <pose>0 0 0.30 0 0 0</pose>
    <link name='base_link'>
      <pose>0 0 0 0 0 0</pose>
      <inertial>
        <pose>0 0 0 0 0 0</pose>
        <mass>0.5</mass>
        <inertia>
          <ixx>0.0601</ixx>
          <ixy>0</ixy>
          <ixz>0</ixz>
          <iyy>0.0151</iyy>
          <iyz>0</iyz>
          <izz>0.075</izz>
        </inertia>
      </inertial>
      <collision name='base_link_collision'>
        <pose>0 0 -0.10 0 0 0</pose>
        <geometry>
          <box>
            <size>0.6 1.2 0.05</size>
          </box>
        </geometry>
        <surface>
          <contact>
            <ode>
              <max_vel>10</max_vel>
              <min_depth>0.01</min_depth>
            </ode>
          </contact>
          <friction>
            <ode>
              <mu>1.0</mu>
              <mu2>1.0</mu2>
            </ode>
          </friction>
        </surface>
      </collision>
      <visual name='base_link_visual'>
        <pose>0 0 0 1.5708 0 1.5708</pose>
        <geometry>
          <mesh>
            <uri>meshes/g3_clean.stl</uri>
            <scale>0.019459 0.019459 0.019459</scale>
          </mesh>
        </geometry>
        <material>
          <ambient>.3 .3 .3 1.0</ambient>
          <diffuse>.3 .3 .3 1.0</diffuse>
        </material>
      </visual>
      <gravity>1</gravity>
      <velocity_decay/>
      <self_collide>0</self_collide>
      <sensor name="imu_sensor" type="imu">
        <always_on>1</always_on>
        <update_rate>250</update_rate>
        <imu>
          <angular_velocity>
            <x><noise type="gaussian"><mean>0</mean><stddev>0.0003394</stddev><dynamic_bias_stddev>3.8785e-05</dynamic_bias_stddev><dynamic_bias_correlation_time>1000</dynamic_bias_correlation_time></noise></x>
            <y><noise type="gaussian"><mean>0</mean><stddev>0.0003394</stddev><dynamic_bias_stddev>3.8785e-05</dynamic_bias_stddev><dynamic_bias_correlation_time>1000</dynamic_bias_correlation_time></noise></y>
            <z><noise type="gaussian"><mean>0</mean><stddev>0.0003394</stddev><dynamic_bias_stddev>3.8785e-05</dynamic_bias_stddev><dynamic_bias_correlation_time>1000</dynamic_bias_correlation_time></noise></z>
          </angular_velocity>
          <linear_acceleration>
            <x><noise type="gaussian"><mean>0</mean><stddev>0.004</stddev><dynamic_bias_stddev>0.006</dynamic_bias_stddev><dynamic_bias_correlation_time>300</dynamic_bias_correlation_time></noise></x>
            <y><noise type="gaussian"><mean>0</mean><stddev>0.004</stddev><dynamic_bias_stddev>0.006</dynamic_bias_stddev><dynamic_bias_correlation_time>300</dynamic_bias_correlation_time></noise></y>
            <z><noise type="gaussian"><mean>0</mean><stddev>0.004</stddev><dynamic_bias_stddev>0.006</dynamic_bias_stddev><dynamic_bias_correlation_time>300</dynamic_bias_correlation_time></noise></z>
          </linear_acceleration>
        </imu>
      </sensor>
      <sensor name="air_pressure_sensor" type="air_pressure">
        <always_on>1</always_on>
        <update_rate>50</update_rate>
        <air_pressure>
          <pressure><noise type="gaussian"><mean>0</mean><stddev>0.01</stddev></noise></pressure>
        </air_pressure>
      </sensor>
      <sensor name="magnetometer_sensor" type="magnetometer">
        <always_on>1</always_on>
        <update_rate>100</update_rate>
        <magnetometer>
          <x><noise type="gaussian"><stddev>0.0001</stddev></noise></x>
          <y><noise type="gaussian"><stddev>0.0001</stddev></noise></y>
          <z><noise type="gaussian"><stddev>0.0001</stddev></noise></z>
        </magnetometer>
      </sensor>
      <sensor name="navsat_sensor" type="navsat">
        <always_on>1</always_on>
        <update_rate>30</update_rate>
      </sensor>
    </link>

    <link name='rotor_puller'>
      <pose>0.32 0 0.0 0 1.57 0</pose>
      <inertial>
        <pose>0 0 0 0 0 0</pose>
        <mass>0.005</mass>
        <inertia>
          <ixx>9.75e-07</ixx>
          <ixy>0</ixy>
          <ixz>0</ixz>
          <iyy>0.000166704</iyy>
          <iyz>0</iyz>
          <izz>0.000167604</izz>
        </inertia>
      </inertial>
      <collision name='rotor_puller_collision'>
        <pose>0.0 0 0.0 0 0 0</pose>
        <geometry>
          <cylinder>
            <length>0.005</length>
            <radius>0.1</radius>
          </cylinder>
        </geometry>
        <surface>
          <contact><ode/></contact>
          <friction><ode/></friction>
        </surface>
      </collision>
      <visual name='rotor_puller_visual'>
        <pose>0 0 -0.09 0 0 0</pose>
        <geometry>
          <mesh>
            <scale>1 1 1</scale>
            <uri>model://rc_cessna/meshes/iris_prop_ccw.dae</uri>
          </mesh>
        </geometry>
        <material>
          <ambient>.175 .175 .175 1.0</ambient>
          <diffuse>.175 .175 .175 1.0</diffuse>
        </material>
      </visual>
      <gravity>1</gravity>
      <velocity_decay/>
      <self_collide>0</self_collide>
    </link>
    <joint name='rotor_puller_joint' type='revolute'>
      <child>rotor_puller</child>
      <parent>base_link</parent>
      <axis>
        <xyz>1 0 0</xyz>
        <limit><lower>-1e+16</lower><upper>1e+16</upper></limit>
        <dynamics><spring_reference>0</spring_reference><spring_stiffness>0</spring_stiffness></dynamics>
        <use_parent_model_frame>1</use_parent_model_frame>
      </axis>
    </joint>

    <link name='nose_wheel'>
      <pose>0.25 0 -0.24 0 0 0</pose>
      <inertial>
        <mass>0.03</mass>
        <inertia>
          <ixx>0.00002</ixx><ixy>0</ixy><ixz>0</ixz>
          <iyy>0.00002</iyy><iyz>0</iyz><izz>0.00002</izz>
        </inertia>
      </inertial>
      <collision name='nose_wheel_collision'>
        <pose>0 0 0 1.5707 0 0</pose>
        <geometry>
          <cylinder><radius>0.06</radius><length>0.03</length></cylinder>
        </geometry>
        <surface>
          <contact><ode><max_vel>5</max_vel><min_depth>0.001</min_depth></ode></contact>
          <friction><ode><mu>1.0</mu><mu2>1.0</mu2></ode></friction>
        </surface>
      </collision>
      <visual name='nose_wheel_visual'>
        <pose>0 0 0 1.5707 0 0</pose>
        <geometry>
          <cylinder><radius>0.06</radius><length>0.03</length></cylinder>
        </geometry>
        <material><ambient>.05 .05 .05 1.0</ambient><diffuse>.05 .05 .05 1.0</diffuse></material>
      </visual>
    </link>
    <joint name='nose_wheel_joint' type='revolute'>
      <parent>base_link</parent>
      <child>nose_wheel</child>
      <axis>
        <xyz>0 1 0</xyz>
        <limit><lower>-1e+16</lower><upper>1e+16</upper></limit>
        <dynamics><damping>0.002</damping></dynamics>
        <use_parent_model_frame>1</use_parent_model_frame>
      </axis>
    </joint>

    <link name='left_main_wheel'>
      <pose>-0.15 0.25 -0.24 0 0 0</pose>
      <inertial>
        <mass>0.05</mass>
        <inertia>
          <ixx>0.00003</ixx><ixy>0</ixy><ixz>0</ixz>
          <iyy>0.00003</iyy><iyz>0</iyz><izz>0.00003</izz>
        </inertia>
      </inertial>
      <collision name='left_main_wheel_collision'>
        <pose>0 0 0 1.5707 0 0</pose>
        <geometry>
          <cylinder><radius>0.07</radius><length>0.035</length></cylinder>
        </geometry>
        <surface>
          <contact><ode><max_vel>5</max_vel><min_depth>0.001</min_depth></ode></contact>
          <friction><ode><mu>1.2</mu><mu2>1.2</mu2></ode></friction>
        </surface>
      </collision>
      <visual name='left_main_wheel_visual'>
        <pose>0 0 0 1.5707 0 0</pose>
        <geometry>
          <cylinder><radius>0.07</radius><length>0.035</length></cylinder>
        </geometry>
        <material><ambient>.05 .05 .05 1.0</ambient><diffuse>.05 .05 .05 1.0</diffuse></material>
      </visual>
    </link>
    <joint name='left_main_wheel_joint' type='revolute'>
      <parent>base_link</parent>
      <child>left_main_wheel</child>
      <axis>
        <xyz>0 1 0</xyz>
        <limit><lower>-1e+16</lower><upper>1e+16</upper></limit>
        <dynamics><damping>0.002</damping></dynamics>
        <use_parent_model_frame>1</use_parent_model_frame>
      </axis>
    </joint>

    <link name='right_main_wheel'>
      <pose>-0.15 -0.25 -0.24 0 0 0</pose>
      <inertial>
        <mass>0.05</mass>
        <inertia>
          <ixx>0.00003</ixx><ixy>0</ixy><ixz>0</ixz>
          <iyy>0.00003</iyy><iyz>0</iyz><izz>0.00003</izz>
        </inertia>
      </inertial>
      <collision name='right_main_wheel_collision'>
        <pose>0 0 0 1.5707 0 0</pose>
        <geometry>
          <cylinder><radius>0.07</radius><length>0.035</length></cylinder>
        </geometry>
        <surface>
          <contact><ode><max_vel>5</max_vel><min_depth>0.001</min_depth></ode></contact>
          <friction><ode><mu>1.2</mu><mu2>1.2</mu2></ode></friction>
        </surface>
      </collision>
      <visual name='right_main_wheel_visual'>
        <pose>0 0 0 1.5707 0 0</pose>
        <geometry>
          <cylinder><radius>0.07</radius><length>0.035</length></cylinder>
        </geometry>
        <material><ambient>.05 .05 .05 1.0</ambient><diffuse>.05 .05 .05 1.0</diffuse></material>
      </visual>
    </link>
    <joint name='right_main_wheel_joint' type='revolute'>
      <parent>base_link</parent>
      <child>right_main_wheel</child>
      <axis>
        <xyz>0 1 0</xyz>
        <limit><lower>-1e+16</lower><upper>1e+16</upper></limit>
        <dynamics><damping>0.002</damping></dynamics>
        <use_parent_model_frame>1</use_parent_model_frame>
      </axis>
    </joint>

    <link name="left_elevon">
      <inertial>
        <mass>0.00000001</mass>
        <inertia>
          <ixx>0.000001</ixx><ixy>0.0</ixy><iyy>0.000001</iyy><ixz>0.0</ixz><iyz>0.0</iyz><izz>0.000001</izz>
        </inertia>
        <pose>0 0.3 0 0 0 0</pose>
      </inertial>
      <visual name='left_elevon_visual'>
        <pose>0 0 0 0 0 0</pose>
        <geometry>
          <box>
            <size>0.15 0.4 0.01</size>
          </box>
        </geometry>
        <transparency>1.0</transparency>
      </visual>
    </link>
    <link name="right_elevon">
      <inertial>
        <mass>0.00000001</mass>
        <inertia>
          <ixx>0.000001</ixx><ixy>0.0</ixy><iyy>0.000001</iyy><ixz>0.0</ixz><iyz>0.0</iyz><izz>0.000001</izz>
        </inertia>
        <pose>0 -0.3 0 0 0 0</pose>
      </inertial>
      <visual name='right_elevon_visual'>
        <pose>0 0 0 0 0 0</pose>
        <geometry>
          <box>
            <size>0.15 0.4 0.01</size>
          </box>
        </geometry>
        <transparency>1.0</transparency>
      </visual>
    </link>

    <joint name='servo_0' type='revolute'>
      <parent>base_link</parent>
      <child>left_elevon</child>
      <pose>-0.32 0.3 0 0 0 0</pose>
      <axis>
        <xyz>0 1 0</xyz>
        <limit><lower>-0.52</lower><upper>0.52</upper></limit>
        <dynamics><damping>1.000</damping></dynamics>
      </axis>
      <physics><ode><implicit_spring_damper>1</implicit_spring_damper></ode></physics>
    </joint>
    <plugin filename="gz-sim-joint-position-controller-system" name="gz::sim::systems::JointPositionController">
      <joint_name>servo_0</joint_name>
      <sub_topic>servo_0</sub_topic>
      <p_gain>10</p_gain>
      <i_gain>0</i_gain>
      <d_gain>0</d_gain>
    </plugin>

    <joint name='servo_1' type='revolute'>
      <parent>base_link</parent>
      <child>right_elevon</child>
      <pose>-0.32 -0.3 0 0 0 0</pose>
      <axis>
        <xyz>0 1 0</xyz>
        <limit><lower>-0.52</lower><upper>0.52</upper></limit>
        <dynamics><damping>1.000</damping></dynamics>
      </axis>
      <physics><ode><implicit_spring_damper>1</implicit_spring_damper></ode></physics>
    </joint>
    <plugin filename="gz-sim-joint-position-controller-system" name="gz::sim::systems::JointPositionController">
      <joint_name>servo_1</joint_name>
      <sub_topic>servo_1</sub_topic>
      <p_gain>10</p_gain>
      <i_gain>0</i_gain>
      <d_gain>0</d_gain>
    </plugin>

    <plugin filename="gz-sim-advanced-lift-drag-system" name="gz::sim::systems::AdvancedLiftDrag">
      <a0>0.0</a0>
      <CL0>0.15</CL0>
      <AR>3.5</AR>
      <eff>0.9</eff>
      <CLa>4.0</CLa>
      <CD0>0.04</CD0>
      <Cem0>0.0</Cem0>
      <Cema>-0.4</Cema>
      <CYb>-0.2</CYb>
      <Cellb>-0.05</Cellb>
      <Cenb>0.05</Cenb>
      <CDp>0.0</CDp>
      <CYp>0.0</CYp>
      <CLp>0.0</CLp>
      <Cellp>-0.4</Cellp>
      <Cemp>0.0</Cemp>
      <Cenp>-0.03</Cenp>
      <CDq>0.0</CDq>
      <CYq>0.0</CYq>
      <CLq>4.0</CLq>
      <Cellq>0.0</Cellq>
      <Cemq>-6.0</Cemq>
      <Cenq>0.0</Cenq>
      <CDr>0.0</CDr>
      <CYr>0.1</CYr>
      <CLr>0.0</CLr>
      <Cellr>0.05</Cellr>
      <Cemr>0.0</Cemr>
      <Cenr>-0.05</Cenr>
      <alpha_stall>0.30</alpha_stall>
      <CLa_stall>-3.0</CLa_stall>
      <CDa_stall>-0.7</CDa_stall>
      <Cema_stall>0</Cema_stall>
      <cp>-0.05 0.0 0.0</cp>
      <area>0.7</area>
      <mac>0.5</mac>
      <air_density>1.2041</air_density>
      <forward>1 0 0</forward>
      <upward>0 0 1</upward>
      <link_name>base_link</link_name>
      <num_ctrl_surfaces>2</num_ctrl_surfaces>
      <control_surface>
        <name>servo_0</name>
        <index>0</index>
        <direction>1</direction>
        <CD_ctrl>-0.00006</CD_ctrl>
        <CY_ctrl>0.0</CY_ctrl>
        <CL_ctrl>-0.012</CL_ctrl>
        <Cell_ctrl>-0.0033</Cell_ctrl>
        <Cem_ctrl>0.011</Cem_ctrl>
        <Cen_ctrl>-0.00006</Cen_ctrl>
      </control_surface>
      <control_surface>
        <name>servo_1</name>
        <index>1</index>
        <direction>1</direction>
        <CD_ctrl>-0.00006</CD_ctrl>
        <CY_ctrl>0.0</CY_ctrl>
        <CL_ctrl>-0.012</CL_ctrl>
        <Cell_ctrl>0.0033</Cell_ctrl>
        <Cem_ctrl>0.011</Cem_ctrl>
        <Cen_ctrl>0.00006</Cen_ctrl>
      </control_surface>
    </plugin>

    <plugin filename="gz-sim-multicopter-motor-model-system" name="gz::sim::systems::MulticopterMotorModel">
      <jointName>rotor_puller_joint</jointName>
      <linkName>rotor_puller</linkName>
      <turningDirection>cw</turningDirection>
      <timeConstantUp>0.0125</timeConstantUp>
      <timeConstantDown>0.025</timeConstantDown>
      <maxRotVelocity>3500</maxRotVelocity>
      <motorConstant>7.0e-06</motorConstant>
      <momentConstant>0.01</momentConstant>
      <commandSubTopic>command/motor_speed</commandSubTopic>
      <motorNumber>0</motorNumber>
      <rotorDragCoefficient>8.06428e-05</rotorDragCoefficient>
      <rollingMomentCoefficient>1e-06</rollingMomentCoefficient>
      <rotorVelocitySlowdownSim>20</rotorVelocitySlowdownSim>
      <motorType>velocity</motorType>
    </plugin>
  </model>
</sdf>

